Workbook

Sheet RESUMEN
A1: Costos por Procesos — v3
A2: Modelo afinado TrongkAI · Fuente: Excel equipo 03-jul-2026 · Costo VARIABLE de procesamiento por ton de materia seca
A4: INDICADORES CLAVE
A5: Ruta SACO (Excel origen) | B5: =RUTAS!E5 -> 4938613.2 | C5: CLP/día
A6: Ruta MAXISACO (Excel origen) | B6: =RUTAS!E6 -> 1976697.4 | C6: CLP/día
A7: Costo por ton MP seca — SACO | B7: =RUTAS!F5 -> 194722.64 | C7: CLP/ton
A8: Costo por ton MP seca — MAXISACO | B8: =RUTAS!F6 -> 77938.424 | C8: CLP/ton
A9: Ahorro si se elige maxisaco | B9: =RUTAS!E13 -> 89755024 | C9: CLP/mes
A10: Ruta más barata (maxisaco+tricanter+residual) | B10: =RUTAS!F9 -> 65606.418 | C10: CLP/ton
A11: MP seca final por día | B11: =MP_SECA_FIN -> 25.362296 | C11: ton/día
A12: Toneladas a procesar por día | B12: =TON_PROCESO -> 82.5 | C12: ton/día
A14: LA REGLA DE ORO
A15: • Este modelo mide el costo VARIABLE de procesamiento por tonelada de MATERIA SECA.
A16: • NO incluye: arriendos PEF/Tricanter, leyes sociales (x1,35), fletes, overhead ni MMPP.
A17: • El OPEX completo del piloto vive en la plataforma (trongkai-web.vercel.app/simulacion): 19.114 CLP/kg SKU.
A18: • Nunca comparar 195 CLP/kg (materia seca, variable) contra 19.114 CLP/kg (SKU final, completo).
A19: • Hojas: PARAMETROS (editar azul) → FLUJO MASA → COSTOS ETAPAS → RUTAS → POR VALIDAR.
A22: LEYENDA DE COLORES
A23: Azul = input editable · Negro = fórmula · Verde = link entre hojas · Amarillo = por validar con el equipo

Sheet PARAMETROS
A1: Parámetros del modelo
A2: Celdas AZULES = editables. Todo el modelo recalcula al cambiarlas. Fuente: costos por procesos (3).xlsx — equipo 03-jul-2026
A4: TARIFAS Y CAMBIO
A5: Energía eléctrica | B5: 270 | C5: CLP/kWh | D5: Excel equipo 03-jul-2026. Validar si incluye potencia y cargos fijos
A6: Agua | B6: 800 | C6: CLP/m³ | D6: Canon equipo
A7: Alcantarillado / tratamiento | B7: 950 | C7: CLP/m³ | D7: POR VALIDAR si se paga
A8: Agua total limpieza | B8: =B6+B7 -> 1750 | C8: CLP/m³ | D8: Agua + alcantarillado
A9: EUR / CLP | B9: 1050 | C9: CLP | D9: Canon equipo
A10: USD / CLP | B10: 900 | C10: CLP | D10: Canon equipo
A11: Costo por muestra laboratorio | B11: 1500 | C11: CLP | D11: Acidez, humedad, estabilidad
A13: OPERACIÓN
A14: Turnos por día | B14: 2 | C14: turnos
A15: Horas por turno | B15: 8 | C15: h
A16: Horas operación/día | B16: =B14*B15 -> 16 | C16: h/día
A17: Camiones por día | B17: 3 | C17: camiones
A18: Toneladas por camión | B18: 22 | C18: ton
A19: Ton MMPP recibidas/día | B19: =B17*B18 -> 66 | C19: ton/día
A20: Humedad ingreso MMPP | B20: 0.6 | C20: % | D20: Canon equipo
A21: Agua incorporada estandarización | B21: 0.25 | C21: m³/ton
A22: Ton a procesar/día | B22: =B19*(1+B21) -> 82.5 | C22: ton/día | D22: MMPP + agua incorporada
A23: Ton MP seca ingreso | B23: =B19*(1-B20) -> 26.4 | C23: ton/día
A24: Pérdida por etapa | B24: 0.005 | C24: % | D24: Uniforme, canon equipo
A25: Recepción mensual | B25: 2000 | C25: ton/mes
A26: Días equivalentes/mes | B26: =B25/B19 -> 30.30303 | C26: días | D26: Recepción mensual / ton día
A28: RRHH (sueldo bruto mensual — sin leyes sociales, réplica Excel)
A29: Laboratorista | B29: 1500000 | C29: CLP/mes | D29: Valor hora en col. E | E29: =B29/B$33 -> 9375
A30: Recepcionista | B30: 1000000 | C30: CLP/mes | E30: =B30/B$33 -> 6250
A31: Operario planta | B31: 1000000 | C31: CLP/mes | E31: =B31/B$33 -> 6250
A32: Supervisor de planta | B32: 1500000 | C32: CLP/mes | E32: =B32/B$33 -> 9375
A33: Horas por mes | B33: 160 | C33: h/mes | D33: Base valor hora (Excel origen). OJO: EERR formal usa x1,35 leyes sociales
A35: PACKAGING E INSUMOS
A36: Saco 25 kg | B36: 3000 | C36: CLP/unidad
A37: Kg por saco | B37: 25 | C37: kg
A38: Maxisaco 800 kg | B38: 10000 | C38: CLP/unidad
A39: Kg por maxisaco | B39: 800 | C39: kg
A40: Pallet (compra) | B40: 28000 | C40: CLP/unidad | D40: 40 sacos por pallet
A41: Arriendo pallet | B41: 1000 | C41: CLP/mes
A42: Desinfectantes por etapa | B42: 802.33 | C42: CLP/día | D42: POR VALIDAR: valor idéntico al EUR de electrodos (posible copia)
A43: Agua limpieza por etapa | B43: 1 | C43: m³/día
A45: REPUESTOS PEF (amortizados por tonelada procesada)
...

Sheet FLUJO MASA
A1: Flujo de masa por etapa
A2: Cadena de humedad y pérdidas (0,5% por etapa). MP seca: 26,4 → 25,36 ton/día en 8 pasos.
A4: Etapa | B4: Proceso | C4: Ton entra | D4: Ton sale | E4: Humedad entra | F4: Humedad sale | G4: MP seca (ton) | H4: Nota
A5: E1 | B5: Recepción MP | C5: 66 | D5: 66 | E5: 0.6 | F5: 0.6 | G5: =MP_SECA_IN -> 26.4 | H5: 3 camiones × 22 ton. Muestreo por camión
A6: E2 | B6: Estandarización | C6: 66 | D6: 82.5 | E6: 0.6 | F6: 0.683 | G6: =G5*(1-PERDIDA) -> 26.268 | H6: Incorpora 0,25 m³ agua/ton
A7: E3 | B7: PEF (electroporación) | C7: 82.5 | D7: 82.5 | E7: 0.683 | F7: 0.683 | G7: =G6*(1-PERDIDA) -> 26.13666 | H7: Repuestos amortizados por ton
A8: E4.1 | B8: Prensado tradicional | C8: 82.5 | D8: 43.56 | E8: 0.683 | F8: 0.4 | G8: =G7*(1-PERDIDA) -> 26.005977 | H8: Alternativa A
A9: E4.2 | B9: Tricanter (centrífugo) | C9: 82.5 | D9: 37.34 | E9: 0.685 | F9: 0.3 | G9: =G7*(1-PERDIDA) -> 26.005977 | H9: Alternativa B — la cadena de masa del Excel origen sigue esta ruta
A10: E5.1 | B10: Deshidratación bomba de calor | C10: 37.15 | D10: 28.9 | E10: 0.3 | F10: 0.1 | G10: =G8*(1-PERDIDA) -> 25.875947 | H10: 80 kW
A11: E5.2 | B11: Deshidratación calor residual | C11: 37.15 | D11: 28.9 | E11: 0.3 | F11: 0.1 | G11: =G8*(1-PERDIDA) -> 25.875947 | H11: Calor residual La Gloria — 4,4x más barata
A12: E6 | B12: Enfriador eléctrico | C12: 28.75 | D12: 28.13 | E12: 0.1 | F12: 0.08 | G12: =G10*(1-PERDIDA) -> 25.746567
A13: E7 | B13: Molienda | C13: 27.99 | D13: 27.99 | E13: 0.08 | F13: 0.08 | G13: =G12*(1-PERDIDA) -> 25.617834
A14: E8.1 | B14: Homogenizado + SACO 25 kg | C14: 27.85 | D14: 27.845472 | E14: 0.08 | F14: 0.08 | G14: =G13*(1-PERDIDA) -> 25.489745 | H14: ~1.114 sacos/día
A15: E8.2 | B15: Homogenizado + MAXISACO 800 kg | C15: 27.71 | D15: 28.32 | E15: 0.08 | F15: 0.1 | G15: =G13*(1-PERDIDA) -> 25.489745 | H15: ~35 maxisacos/día
A16: E9 | B16: Etiquetado y almacenamiento | C16: 28.32 | D16: 28.32 | E16: 0.08 | F16: 0.08 | G16: =G14*(1-PERDIDA) -> 25.362296 | H16: MP seca final del modelo
F18: MP seca final: | G18: =G16 -> 25.362296

Sheet COSTOS ETAPAS
A1: Costos por etapa (CLP/día)
A2: Fórmulas vivas desde PARAMETROS. Columna 'Excel origen' = total del archivo del equipo; Δ debe ser ~0.
A4: Etapa | B4: Proceso | C4: RRHH | D4: kW equipos | E4: Energía | F4: Agua | G4: Desinfect. | H4: Limpieza (1h) | I4: Muestras | J4: Insumos / packaging | K4: Ajuste concil. | L4: TOTAL CLP/día | M4: Excel origen | N4: Δ | O4: CLP/ton MP seca
A5: E1 | B5: Recepción MP | C5: =(H_LAB*1+H_RECEP*1)*CAMIONES -> 46875 | D5: 0 | E5: =D5*HORAS_DIA*TARIFA_KWH -> 0 | F5: =AGUA_LIMP_M3*AGUA_TOTAL -> 1750 | G5: =DESINF -> 802.33 | H5: =H_OP*1 -> 6250 | I5: =3*MUESTRA -> 4500 | J5: 0 | K5: 0 | L5: =SUM(C5,E5:K5) -> 60177.33 | M5: 60177.33 | N5: =L5-M5 -> 0 | O5: =L5/'FLUJO MASA'!G5 -> 2279.4443
A6: E2 | B6: Estandarización | C6: =H_OP*1+H_LAB*0.25 -> 8593.75 | D6: 13.2 | E6: =D6*HORAS_DIA*TARIFA_KWH -> 57024 | F6: =AGUA_LIMP_M3*AGUA_TOTAL+TON_MMPP*AGUA_EST*AGUA_M3 -> 14950 | G6: =DESINF -> 802.33 | H6: =H_OP*1 -> 6250 | I6: =1*MUESTRA -> 1500 | J6: 0 | K6: 6885.17 | L6: =SUM(C6,E6:K6) -> 96005.25 | M6: 96005.25 | N6: =L6-M6 -> 0 | O6: =L6/'FLUJO MASA'!G6 -> 3654.8367
A7: E3 | B7: PEF (electroporación) | C7: =(H_OP*1+H_SUP*1)*CAMIONES -> 46875 | D7: 14 | E7: =D7*HORAS_DIA*TARIFA_KWH -> 60480 | F7: =AGUA_LIMP_M3*AGUA_TOTAL -> 1750 | G7: =DESINF -> 802.33 | H7: =H_OP*1 -> 6250 | I7: 0 | J7: =(ELEC_TON+CAM_TON)*TON_PROCESO -> 161001.59 | K7: 0 | L7: =SUM(C7,E7:K7) -> 277158.92 | M7: 277158.92 | N7: =L7-M7 -> -0.0040625 | O7: =L7/'FLUJO MASA'!G7 -> 10604.221
A8: E4.1 | B8: Prensado tradicional | C8: =H_OP*6 -> 37500 | D8: 24 | E8: =D8*HORAS_DIA*TARIFA_KWH -> 103680 | F8: =AGUA_LIMP_M3*AGUA_TOTAL -> 1750 | G8: =DESINF -> 802.33 | H8: =H_OP*1 -> 6250 | I8: 0 | J8: 0 | K8: 0 | L8: =SUM(C8,E8:K8) -> 149982.33 | M8: 149982.33 | N8: =L8-M8 -> 0 | O8: =L8/'FLUJO MASA'!G8 -> 5767.2254
A9: E4.2 | B9: Tricanter (centrífugo) | C9: =H_OP*6 -> 37500 | D9: 21.6 | E9: =D9*HORAS_DIA*TARIFA_KWH -> 93312 | F9: =AGUA_LIMP_M3*AGUA_TOTAL -> 1750 | G9: =DESINF -> 802.33 | H9: =H_OP*1 -> 6250 | I9: 0 | J9: 0 | K9: 0 | L9: =SUM(C9,E9:K9) -> 139614.33 | M9: 139614.33 | N9: =L9-M9 -> 0 | O9: =L9/'FLUJO MASA'!G9 -> 5368.5478
A10: E5.1 | B10: Deshidratación bomba de calor | C10: =H_OP*6 -> 37500 | D10: 80 | E10: =D10*HORAS_DIA*TARIFA_KWH -> 345600 | F10: =AGUA_LIMP_M3*AGUA_TOTAL -> 1750 | G10: =DESINF -> 802.33 | H10: =H_OP*1 -> 6250 | I10: 0 | J10: 0 | K10: 0 | L10: =SUM(C10,E10:K10) -> 391902.33 | M10: 391902.33 | N10: =L10-M10 -> 0 | O10: =L10/'FLUJO MASA'!G10 -> 15145.43
A11: E5.2 | B11: Deshidratación calor residual | C11: =H_OP*6 -> 37500 | D11: 10 | E11: =D11*HORAS_DIA*TARIFA_KWH -> 43200 | F11: =AGUA_LIMP_M3*AGUA_TOTAL -> 1750 | G11: =DESINF -> 802.33 | H11: =H_OP*1 -> 6250 | I11: 0 | J11: 0 | K11: 0 | L11: =SUM(C11,E11:K11) -> 89502.33 | M11: 89502.33 | N11: =L11-M11 -> 0 | O11: =L11/'FLUJO MASA'!G11 -> 3458.9007
A12: E6 | B12: Enfriador eléctrico | C12: =H_OP*6 -> 37500 | D12: 10 | E12: =D12*HORAS_DIA*TARIFA_KWH -> 43200 | F12: =AGUA_LIMP_M3*AGUA_TOTAL -> 1750 | G12: =DESINF -> 802.33 | H12: =H_OP*1 -> 6250 | I12: 0 | J12: 0 | K12: 0 | L12: =SUM(C12,E12:K12) -> 89502.33 | M12: 89502.33 | N12: =L12-M12 -> 0 | O12: =L12/'FLUJO MASA'!G12 -> 3476.2821
A13: E7 | B13: Molienda | C13: =H_OP*6 -> 37500 | D13: 61.6 | E13: =D13*HORAS_DIA*TARIFA_KWH -> 266112 | F13: =AGUA_LIMP_M3*AGUA_TOTAL -> 1750 | G13: =DESINF -> 802.33 | H13: =H_OP*1 -> 6250 | I13: 0 | J13: 0 | K13: 0 | L13: =SUM(C13,E13:K13) -> 312414.33 | M13: 312414.33 | N13: =L13-M13 -> 0 | O13: =L13/'FLUJO MASA'!G13 -> 12195.189
A14: E8.1 | B14: Homogenizado + SACO 25 kg | C14: =H_OP*6 -> 37500 | D14: 4.48 | E14: =D14*HORAS_DIA*TARIFA_KWH -> 19353.6 | F14: =AGUA_LIMP_M3*AGUA_TOTAL -> 1750 | G14: =DESINF -> 802.33 | H14: =H_OP*1 -> 6250 | I14: =1*MUESTRA -> 1500 | J14: ='FLUJO MASA'!D14*1000/SACO_KG*SACO_CLP -> 3341456.6 | K14: 0 | L14: =SUM(C14,E14:K14) -> 3408612.6 | M14: 3408612.6 | N14: =L14-M14 -> 0 | O14: =L14/'FLUJO MASA'!G14 -> 133724.86
A15: E8.2 | B15: Homogenizado + MAXISACO 800 kg | C15: =H_OP*2 -> 12500 | D15: 4.48 | E15: =D15*HORAS_DIA*TARIFA_KWH -> 19353.6 | F15: =AGUA_LIMP_M3*AGUA_TOTAL -> 1750 | G15: =DESINF -> 802.33 | H15: =H_OP*1 -> 6250 | I15: =1*MUESTRA -> 1500 | J15: =379540.85*(MAXI_CLP/10000) -> 379540.85 | K15: 25000 | L15: =SUM(C15,E15:K15) -> 446696.78 | M15: 446696.78 | N15: =L15-M15 -> 0 | O15: =L15/'FLUJO MASA'!G15 -> 17524.568
A16: E9 | B16: Etiquetado y almacenamiento | C16: =H_OP*5+H_LAB*0.25 -> 33593.75 | D16: 5 | E16: =D16*HORAS_DIA*TARIFA_KWH -> 21600 | F16: 0 | G16: 0 | H16: =H_OP*1 -> 6250 | I16: =2*MUESTRA -> 3000 | J16: 0 | K16: 88414.06 | L16: =SUM(C16,E16:K16) -> 152857.81 | M16: 152857.81 | N16: =L16-M16 -> 0 | O16: =L16/'FLUJO MASA'!G16 -> 6026.9704

Sheet RUTAS
A1: Comparativo de rutas
A2: Cada ruta = E1+E2+E3 + prensado + secado + E6+E7 + packaging + E9. El Excel origen usa E4.1 + E5.1 (rutas 'base').
A4: Ruta | B4: Prensado | C4: Secado | D4: Packaging | E4: CLP/día | F4: CLP/ton MP seca | G4: CLP/kg MP seca | H4: CLP/mes
A5: SACO base (= Excel origen) | B5: Prensa | C5: Bomba calor | D5: Saco 25 kg | E5: ='COSTOS ETAPAS'!L5+'COSTOS ETAPAS'!L6+'COSTOS ETAPAS'!L7+'COSTOS ETAPAS'!L12+'COSTOS ETAPAS'!L13+'COSTOS ETAPAS'!L16+'COSTOS ETAPAS'!L8+'COSTOS ETAPAS'!L10+'COSTOS ETAPAS'!L14 -> 4938613.2 | F5: =E5/MP_SECA_FIN -> 194722.64 | G5: =F5/1000 -> 194.72264 | H5: =E5*DIAS_MES -> 1.4965495e+08
A6: MAXISACO base (= Excel origen) | B6: Prensa | C6: Bomba calor | D6: Maxisaco 800 kg | E6: ='COSTOS ETAPAS'!L5+'COSTOS ETAPAS'!L6+'COSTOS ETAPAS'!L7+'COSTOS ETAPAS'!L12+'COSTOS ETAPAS'!L13+'COSTOS ETAPAS'!L16+'COSTOS ETAPAS'!L8+'COSTOS ETAPAS'!L10+'COSTOS ETAPAS'!L15 -> 1976697.4 | F6: =E6/MP_SECA_FIN -> 77938.424 | G6: =F6/1000 -> 77.938424 | H6: =E6*DIAS_MES -> 59899921
A7: SACO + calor residual | B7: Prensa | C7: Calor residual | D7: Saco 25 kg | E7: ='COSTOS ETAPAS'!L5+'COSTOS ETAPAS'!L6+'COSTOS ETAPAS'!L7+'COSTOS ETAPAS'!L12+'COSTOS ETAPAS'!L13+'COSTOS ETAPAS'!L16+'COSTOS ETAPAS'!L8+'COSTOS ETAPAS'!L11+'COSTOS ETAPAS'!L14 -> 4636213.2 | F7: =E7/MP_SECA_FIN -> 182799.43 | G7: =F7/1000 -> 182.79943 | H7: =E7*DIAS_MES -> 1.4049131e+08
A8: MAXISACO + calor residual | B8: Prensa | C8: Calor residual | D8: Maxisaco 800 kg | E8: ='COSTOS ETAPAS'!L5+'COSTOS ETAPAS'!L6+'COSTOS ETAPAS'!L7+'COSTOS ETAPAS'!L12+'COSTOS ETAPAS'!L13+'COSTOS ETAPAS'!L16+'COSTOS ETAPAS'!L8+'COSTOS ETAPAS'!L11+'COSTOS ETAPAS'!L15 -> 1674297.4 | F8: =E8/MP_SECA_FIN -> 66015.213 | G8: =F8/1000 -> 66.015213 | H8: =E8*DIAS_MES -> 50736285
A9: MAXISACO + tricanter + residual (más barata) | B9: Tricanter | C9: Calor residual | D9: Maxisaco 800 kg | E9: ='COSTOS ETAPAS'!L5+'COSTOS ETAPAS'!L6+'COSTOS ETAPAS'!L7+'COSTOS ETAPAS'!L12+'COSTOS ETAPAS'!L13+'COSTOS ETAPAS'!L16+'COSTOS ETAPAS'!L9+'COSTOS ETAPAS'!L11+'COSTOS ETAPAS'!L15 -> 1663929.4 | F9: =E9/MP_SECA_FIN -> 65606.418 | G9: =F9/1000 -> 65.606418 | H9: =E9*DIAS_MES -> 50422103
A11: DECISIÓN PACKAGING
A12: Ahorro maxisaco vs saco (CLP/día) | E12: =E5-E6 -> 2961915.8
A13: Ahorro maxisaco vs saco (CLP/mes) | E13: =(E5-E6)*DIAS_MES -> 89755024
A14: Factor de costo saco / maxisaco | E14: =E5/E6 -> 2.4984164
A15: Ahorro calor residual vs bomba calor (CLP/día) | E15: =E5-E7 -> 302400
A17: ⚠ El packaging en saco 25 kg es el 69% del costo de la ruta base: decisión comercial n.°1 del piloto.

Sheet POR VALIDAR
A1: Pendientes por validar con el equipo
A2: Cada ítem cambia el resultado del modelo. Actualizar PARAMETROS cuando se confirme.
A4: # | B4: Tema | C4: Detalle | D4: Impacto si cambia | E4: Dueño sugerido | F4: Estado
A5: 1 | B5: Alcantarillado 950 CLP/m³ | C5: ¿Se paga alcantarillado/tratamiento sobre el agua? | D5: Agua limpieza por etapa: 1.750 → 800 CLP/día | E5: Operaciones | F5: Abierto
A6: 2 | B6: Duración electrodos PEF | C6: Excel dice 300 h; el sistema de la máquina indica 200 h | D6: Repuestos: 702 → 1.053 CLP/ton (+50%) | E6: Jefe planta | F6: Abierto
A7: 3 | B7: Desinfectantes 802,33 CLP | C7: Valor idéntico al precio EUR de electrodos (posible error de copia) | D7: Menor (≈800 CLP/día/etapa) | E7: Operaciones | F7: Abierto
A8: 4 | B8: Ruta cruzada del Excel origen | C8: El costo total usa prensa (E4.1) pero la cadena de masa sigue al tricanter (E4.2) | D8: Definir ruta operativa real; este modelo separa las 4 rutas | E8: Jefe planta | F8: Corregido aquí
A9: 5 | B9: E8.2 maxisaco multiplicador | C9: La fuente mezcla multiplicadores (≈51.000 CLP/día de diferencia) | D9: Maxisaco seguiría siendo 2,4x más barato | E9: Finanzas | F9: Abierto
A10: 6 | B10: Tarifa eléctrica 270 CLP/kWh | C10: ¿Incluye cargos de potencia y cargos fijos? | D10: Driver n.°2 del costo (energía = 2,5x la estimación previa) | E10: Finanzas | F10: Abierto
A11: 7 | B11: Dotación mensual RRHH | C11: Excel indica 'Laboratorista/mes 3 · 0,75' — ambiguo (¿FTE o personas?) | D11: RRHH por etapa | E11: RRHH | F11: Abierto
A12: 8 | B12: Leyes sociales | C12: El Excel no aplica x1,35 sobre sueldos | D12: RRHH +35% en EERR formal (la plataforma sí lo aplica) | E12: Finanzas | F12: Documentado
